The following values were not passed to `accelerate launch` and had defaults used instead:
	`--num_processes` was set to a value of `0`
	`--num_machines` was set to a value of `1`
	`--mixed_precision` was set to a value of `'no'`
	`--dynamo_backend` was set to a value of `'no'`
To avoid this warning pass in values for each of the problematic parameters or run `accelerate config`.
/home/vulamanh/miniconda3/envs/graphrag_env/bin/python: can't open file '/home/vulamanh/Documents/nanographrag/training_embedding/training_embedding/make_multilingual.py': [Errno 2] No such file or directory
Traceback (most recent call last):
  File "/home/vulamanh/miniconda3/envs/graphrag_env/bin/accelerate", line 8, in <module>
    sys.exit(main())
             ^^^^^^
  File "/home/vulamanh/miniconda3/envs/graphrag_env/lib/python3.12/site-packages/accelerate/commands/accelerate_cli.py", line 48, in main
    args.func(args)
  File "/home/vulamanh/miniconda3/envs/graphrag_env/lib/python3.12/site-packages/accelerate/commands/launch.py", line 1194, in launch_command
    simple_launcher(args)
  File "/home/vulamanh/miniconda3/envs/graphrag_env/lib/python3.12/site-packages/accelerate/commands/launch.py", line 780, in simple_launcher
    raise subprocess.CalledProcessError(returncode=process.returncode, cmd=cmd)
subprocess.CalledProcessError: Command '['/home/vulamanh/miniconda3/envs/graphrag_env/bin/python', 'training_embedding/make_multilingual.py', '--config', 'training_embedding/training_config.yaml']' returned non-zero exit status 2.
